Workbook

Sheet Profile and Overview
B2: A Term Paper on "The Application of the Dynamic Asset Allocation Strategy and Comparisons with Other Alternative Investment Strategies"
B7: Course: F-503: Financial Derivatives
B9: Name: Ifta Hider Rahman
B11: MBA Batch
B12: Department of Finance
B13: Faculty of Business Studies (FBS)
B14: University of Dhaka, Dhaka-1000
B17: Project Overview: This Excel model analyzes Dynamic Asset Allocation strategies for a portfolio of eight DSE stocks and a risk-free asset. Utilizing actual price/dividend data and binomial option modeling, it demonstrates dynamic rebalancing, portfolio insurance, and risk-return tradeoffs versus alternative strategies.
B23: Main Features: - Data-driven delta hedging and portfolio insurance modeling - Dynamic vs. static (rebalanced/unrebalanced) portfolio analysis - Stepwise portfolio adjustment using real market prices - Comprehensive risk and return output tables
B30: Instructions: - Explore each tab for calculations, figures, and explanatory notes. - All steps are labeled for clarity; summary results are found at the end.

Sheet Assumptions
B2: Assumptions: | C2: Amount | E2: Notes
B3: Period: 2024 Q1 to 2025 Q3
B4: 1. Amount of Investment | C4: 1000000
B5: 2. Risk Free Rate | E5: Weighted average cut off yield of 91 day t-bill
B6: 3. Strike Price | C6: =C4*(1+0.05) -> 1050000 | E6: 5% higher than initial investment
B7: 4. Investment will be made in equal weight among 8 securities
B8: 5. Continuous compounding of risk free rate will be used
B9: 7. Call and put strike prices are assumed to be equal at expiration time

Sheet Stock Selection
B2: Stock Selection
B4: Firm | C4: Trading Code | D4: Sector | E4: Market Capitalization | F4: P/E Multiple | G4: Dividend Yield | H4: Net Asset Value Per Share
B5: United Commercial Bank Ltd | C5: UCB | D5: Bank | E5: 15658.797 | F5: 23.67 | H5: 26.42
B6: IDLC Finance Ltd | C6: IDLC | D6: Financial Institutions | E6: 15364.216 | F6: 6.79 | G6: 0.0459 | H6: 48.26
B7: Grameenphone Ltd | C7: GP | D7: Telecommunication | E7: 374978.32 | F7: 12.02 | G7: 0.1021 | H7: 47.95
B8: Bata Shoe Company Bangladesh Ltd | C8: BATASHOE | D8: Tannery Industries | E8: 11617.056 | F8: 41.88 | G8: 0.0491 | H8: 220.22
B9: Renata Ltd | C9: RENATA | D9: Pharmaceuticals & Chemicals | E9: 44823.388 | F9: 24.43 | G9: 0.0119 | H9: 295.56
B10: Walton Hi-Tech Industries Ltd | C10: WALTONHIL | D10: Engineering | E10: 121259.19 | F10: 11.87 | G10: 0.0431 | H10: 399.74
B11: Rak Ceramics Bangladesh Ltd | C11: RAKC | D11: Ceramics Sector | E11: 9115.733 | F11: 11.88 | G11: 0.0391 | H11: 78.28
B12: Olympic Industries Ltd | C12: OLYMPIC | D12: Food & Allied | E12: 28071.42 | F12: 14.43 | G12: 0.0076 | H12: 53.29

Sheet Data
C1: United Commercial Bank Ltd (UCBL) | K1: IDLC Finance Ltd (IDLC) | S1: Grameenphone Ltd (GP) | AA1: Bata Shoe Company Bangladesh Ltd (BATA) | AI1: Renata Ltd (RNTL) | AQ1: Walton Hi-Tech Industries Ltd (WALT) | AY1: Rak Ceramics Bangladesh Ltd (RAKC) | BG1: Olympic Industries Ltd (OLIS)
B2: Date | C2: Price | D2: Stock Dividend (%) | E2: Right Ratio (%) | F2: Right Offer Price (TK.) | G2: Stock Dividend and Righ Share Adjusted Price | H2: Cash Dividend (TK.) | I2: Total Return (%) | J2: Date | K2: =C2 -> Price | L2: =D2 -> Stock Dividend (%) | M2: =E2 -> Right Ratio (%) | N2: =F2 -> Right Offer Price (TK.) | O2: =G2 -> Stock Dividend and Righ Share Adjusted Price | P2: =H2 -> Cash Dividend (TK.) | Q2: =I2 -> Total Return (%) | R2: Date | S2: =C2 -> Price | T2: =D2 -> Stock Dividend (%) | U2: =E2 -> Right Ratio (%) | V2: =F2 -> Right Offer Price (TK.) | W2: =G2 -> Stock Dividend and Righ Share Adjusted Price | X2: =H2 -> Cash Dividend (TK.) | Y2: =I2 -> Total Return (%) | Z2: Date | AA2: =C2 -> Price | AB2: =D2 -> Stock Dividend (%) | AC2: =E2 -> Right Ratio (%) | AD2: =F2 -> Right Offer Price (TK.) | AE2: =G2 -> Stock Dividend and Righ Share Adjusted Price | AF2: =H2 -> Cash Dividend (TK.) | AG2: =I2 -> Total Return (%) | AH2: Date | AI2: =AA2 -> Price | AJ2: =AB2 -> Stock Dividend (%) | AK2: =AC2 -> Right Ratio (%) | AL2: =AD2 -> Right Offer Price (TK.) | AM2: =AE2 -> Stock Dividend and Righ Share Adjusted Price | AN2: =AF2 -> Cash Dividend (TK.) | AO2: =AG2 -> Total Return (%) | AP2: Date | AQ2: =C2 -> Price | AR2: =D2 -> Stock Dividend (%) | AS2: =E2 -> Right Ratio (%) | AT2: =F2 -> Right Offer Price (TK.) | AU2: =G2 -> Stock Dividend and Righ Share Adjusted Price | AV2: =H2 -> Cash Dividend (TK.) | AW2: =I2 -> Total Return (%) | AX2: Date | AY2: =C2 -> Price | AZ2: =D2 -> Stock Dividend (%) | BA2: =E2 -> Right Ratio (%) | BB2: =F2 -> Right Offer Price (TK.) | BC2: =G2 -> Stock Dividend and Righ Share Adjusted Price | BD2: =H2 -> Cash Dividend (TK.) | BE2: =I2 -> Total Return (%) | BF2: Date | BG2: =C2 -> Price | BH2: =D2 -> Stock Dividend (%) | BI2: =E2 -> Right Ratio (%) | BJ2: =F2 -> Right Offer Price (TK.) | BK2: =G2 -> Stock Dividend and Righ Share Adjusted Price | BL2: =H2 -> Cash Dividend (TK.) | BM2: =I2 -> Total Return (%)
A3: 2024 Q1 | B3: 45292 | C3: 12.4 | G3: =C3+C3*D3+C3*E3-F3*E3 -> 12.4 | J3: 45292 | K3: 46.5 | O3: =K3+K3*L3+K3*M3-N3*M3 -> 46.5 | R3: 45292 | S3: 286.6 | W3: =S3+S3*T3+S3*U3-V3*U3 -> 286.6 | Z3: 45292 | AA3: 966.6 | AE3: =AA3+AA3*AB3+AA3*AC3-AD3*AC3 -> 966.6 | AH3: 45292 | AI3: 1217.9 | AM3: =AI3+AI3*AJ3+AI3*AK3-AL3*AK3 -> 1217.9 | AP3: 45292 | AQ3: 1047.7 | AU3: =AQ3+AQ3*AR3+AQ3*AS3-AT3*AS3 -> 1047.7 | AX3: 45292 | AY3: 42.9 | BC3: =AY3+AY3*AZ3+AY3*BA3-BB3*BA3 -> 42.9 | BF3: 45292 | BG3: 151.2 | BK3: =BG3+BG3*BH3+BG3*BI3-BJ3*BI3 -> 151.2
B4: 45293 | C4: 12.4 | G4: =C4+C4*D4+C4*E4-F4*E4 -> 12.4 | I4: =LN((G4+H4)/G3) -> 0 | J4: 45293 | K4: 46.5 | O4: =K4+K4*L4+K4*M4-N4*M4 -> 46.5 | Q4: =LN((O4+P4)/O3) -> 0 | R4: 45293 | S4: 286.6 | W4: =S4+S4*T4+S4*U4-V4*U4 -> 286.6 | Y4: =LN((W4+X4)/W3) -> 0 | Z4: 45293 | AA4: 961.3 | AE4: =AA4+AA4*AB4+AA4*AC4-AD4*AC4 -> 961.3 | AG4: =LN((AE4+AF4)/AE3) -> -0.0054982243 | AH4: 45293 | AI4: 1217.9 | AM4: =AI4+AI4*AJ4+AI4*AK4-AL4*AK4 -> 1217.9 | AO4: =LN((AM4+AN4)/AM3) -> 0 | AP4: 45293 | AQ4: 1047.7 | AU4: =AQ4+AQ4*AR4+AQ4*AS4-AT4*AS4 -> 1047.7 | AW4: =LN((AU4+AV4)/AU3) -> 0 | AX4: 45293 | AY4: 42.9 | BC4: =AY4+AY4*AZ4+AY4*BA4-BB4*BA4 -> 42.9 | BE4: =LN((BC4+BD4)/BC3) -> 0 | BF4: 45293 | BG4: 152 | BK4: =BG4+BG4*BH4+BG4*BI4-BJ4*BI4 -> 152 | BM4: =LN((BK4+BL4)/BK3) -> 0.0052770571
B5: 45294 | C5: 12.4 | G5: =C5+C5*D5+C5*E5-F5*E5 -> 12.4 | I5: =LN((G5+H5)/G4) -> 0 | J5: 45294 | K5: 46.5 | O5: =K5+K5*L5+K5*M5-N5*M5 -> 46.5 | Q5: =LN((O5+P5)/O4) -> 0 | R5: 45294 | S5: 286.6 | W5: =S5+S5*T5+S5*U5-V5*U5 -> 286.6 | Y5: =LN((W5+X5)/W4) -> 0 | Z5: 45294 | AA5: 961.2 | AE5: =AA5+AA5*AB5+AA5*AC5-AD5*AC5 -> 961.2 | AG5: =LN((AE5+AF5)/AE4) -> -0.00010403121 | AH5: 45294 | AI5: 1217.9 | AM5: =AI5+AI5*AJ5+AI5*AK5-AL5*AK5 -> 1217.9 | AO5: =LN((AM5+AN5)/AM4) -> 0 | AP5: 45294 | AQ5: 1047.7 | AU5: =AQ5+AQ5*AR5+AQ5*AS5-AT5*AS5 -> 1047.7 | AW5: =LN((AU5+AV5)/AU4) -> 0 | AX5: 45294 | AY5: 42.9 | BC5: =AY5+AY5*AZ5+AY5*BA5-BB5*BA5 -> 42.9 | BE5: =LN((BC5+BD5)/BC4) -> 0 | BF5: 45294 | BG5: 154.3 | BK5: =BG5+BG5*BH5+BG5*BI5-BJ5*BI5 -> 154.3 | BM5: =LN((BK5+BL5)/BK4) -> 0.015018239
B6: 45295 | C6: 12.4 | G6: =C6+C6*D6+C6*E6-F6*E6 -> 12.4 | I6: =LN((G6+H6)/G5) -> 0 | J6: 45295 | K6: 46.5 | O6: =K6+K6*L6+K6*M6-N6*M6 -> 46.5 | Q6: =LN((O6+P6)/O5) -> 0 | R6: 45295 | S6: 286.6 | W6: =S6+S6*T6+S6*U6-V6*U6 -> 286.6 | Y6: =LN((W6+X6)/W5) -> 0 | Z6: 45295 | AA6: 968.6 | AE6: =AA6+AA6*AB6+AA6*AC6-AD6*AC6 -> 968.6 | AG6: =LN((AE6+AF6)/AE5) -> 0.0076692261 | AH6: 45295 | AI6: 1217.9 | AM6: =AI6+AI6*AJ6+AI6*AK6-AL6*AK6 -> 1217.9 | AO6: =LN((AM6+AN6)/AM5) -> 0 | AP6: 45295 | AQ6: 1047.7 | AU6: =AQ6+AQ6*AR6+AQ6*AS6-AT6*AS6 -> 1047.7 | AW6: =LN((AU6+AV6)/AU5) -> 0 | AX6: 45295 | AY6: 42.9 | BC6: =AY6+AY6*AZ6+AY6*BA6-BB6*BA6 -> 42.9 | BE6: =LN((BC6+BD6)/BC5) -> 0 | BF6: 45295 | BG6: 156.3 | BK6: =BG6+BG6*BH6+BG6*BI6-BJ6*BI6 -> 156.3 | BM6: =LN((BK6+BL6)/BK5) -> 0.012878478
B7: 45299 | C7: 12.4 | G7: =C7+C7*D7+C7*E7-F7*E7 -> 12.4 | I7: =LN((G7+H7)/G6) -> 0 | J7: 45299 | K7: 46.5 | O7: =K7+K7*L7+K7*M7-N7*M7 -> 46.5 | Q7: =LN((O7+P7)/O6) -> 0 | R7: 45299 | S7: 286.6 | W7: =S7+S7*T7+S7*U7-V7*U7 -> 286.6 | Y7: =LN((W7+X7)/W6) -> 0 | Z7: 45299 | AA7: 969.4 | AE7: =AA7+AA7*AB7+AA7*AC7-AD7*AC7 -> 969.4 | AG7: =LN((AE7+AF7)/AE6) -> 0.00082559344 | AH7: 45299 | AI7: 1217.9 | AM7: =AI7+AI7*AJ7+AI7*AK7-AL7*AK7 -> 1217.9 | AO7: =LN((AM7+AN7)/AM6) -> 0 | AP7: 45299 | AQ7: 1047.7 | AU7: =AQ7+AQ7*AR7+AQ7*AS7-AT7*AS7 -> 1047.7 | AW7: =LN((AU7+AV7)/AU6) -> 0 | AX7: 45299 | AY7: 42.9 | BC7: =AY7+AY7*AZ7+AY7*BA7-BB7*BA7 -> 42.9 | BE7: =LN((BC7+BD7)/BC6) -> 0 | BF7: 45299 | BG7: 155.5 | BK7: =BG7+BG7*BH7+BG7*BI7-BJ7*BI7 -> 155.5 | BM7: =LN((BK7+BL7)/BK6) -> -0.0051315058
B8: 45300 | C8: 12.4 | G8: =C8+C8*D8+C8*E8-F8*E8 -> 12.4 | I8: =LN((G8+H8)/G7) -> 0 | J8: 45300 | K8: 46.5 | O8: =K8+K8*L8+K8*M8-N8*M8 -> 46.5 | Q8: =LN((O8+P8)/O7) -> 0 | R8: 45300 | S8: 286.6 | W8: =S8+S8*T8+S8*U8-V8*U8 -> 286.6 | Y8: =LN((W8+X8)/W7) -> 0 | Z8: 45300 | AA8: 963 | AE8: =AA8+AA8*AB8+AA8*AC8-AD8*AC8 -> 963 | AG8: =LN((AE8+AF8)/AE7) -> -0.0066239116 | AH8: 45300 | AI8: 1217.9 | AM8: =AI8+AI8*AJ8+AI8*AK8-AL8*AK8 -> 1217.9 | AO8: =LN((AM8+AN8)/AM7) -> 0 | AP8: 45300 | AQ8: 1047.7 | AU8: =AQ8+AQ8*AR8+AQ8*AS8-AT8*AS8 -> 1047.7 | AW8: =LN((AU8+AV8)/AU7) -> 0 | AX8: 45300 | AY8: 42.9 | BC8: =AY8+AY8*AZ8+AY8*BA8-BB8*BA8 -> 42.9 | BE8: =LN((BC8+BD8)/BC7) -> 0 | BF8: 45300 | BG8: 155.2 | BK8: =BG8+BG8*BH8+BG8*BI8-BJ8*BI8 -> 155.2 | BM8: =LN((BK8+BL8)/BK7) -> -0.0019311239
B9: 45301 | C9: 12.4 | G9: =C9+C9*D9+C9*E9-F9*E9 -> 12.4 | I9: =LN((G9+H9)/G8) -> 0 | J9: 45301 | K9: 46.5 | O9: =K9+K9*L9+K9*M9-N9*M9 -> 46.5 | Q9: =LN((O9+P9)/O8) -> 0 | R9: 45301 | S9: 286.6 | W9: =S9+S9*T9+S9*U9-V9*U9 -> 286.6 | Y9: =LN((W9+X9)/W8) -> 0 | Z9: 45301 | AA9: 975 | AE9: =AA9+AA9*AB9+AA9*AC9-AD9*AC9 -> 975 | AG9: =LN((AE9+AF9)/AE8) -> 0.012384059 | AH9: 45301 | AI9: 1217.9 | AM9: =AI9+AI9*AJ9+AI9*AK9-AL9*AK9 -> 1217.9 | AO9: =LN((AM9+AN9)/AM8) -> 0 | AP9: 45301 | AQ9: 1047.7 | AU9: =AQ9+AQ9*AR9+AQ9*AS9-AT9*AS9 -> 1047.7 | AW9: =LN((AU9+AV9)/AU8) -> 0 | AX9: 45301 | AY9: 42.9 | BC9: =AY9+AY9*AZ9+AY9*BA9-BB9*BA9 -> 42.9 | BE9: =LN((BC9+BD9)/BC8) -> 0 | BF9: 45301 | BG9: 155.4 | BK9: =BG9+BG9*BH9+BG9*BI9-BJ9*BI9 -> 155.4 | BM9: =LN((BK9+BL9)/BK8) -> 0.0012878302
B10: 45302 | C10: 12.4 | G10: =C10+C10*D10+C10*E10-F10*E10 -> 12.4 | I10: =LN((G10+H10)/G9) -> 0 | J10: 45302 | K10: 46.5 | O10: =K10+K10*L10+K10*M10-N10*M10 -> 46.5 | Q10: =LN((O10+P10)/O9) -> 0 | R10: 45302 | S10: 286.6 | W10: =S10+S10*T10+S10*U10-V10*U10 -> 286.6 | Y10: =LN((W10+X10)/W9) -> 0 | Z10: 45302 | AA10: 969.1 | AE10: =AA10+AA10*AB10+AA10*AC10-AD10*AC10 -> 969.1 | AG10: =LN((AE10+AF10)/AE9) -> -0.0060696653 | AH10: 45302 | AI10: 1217.9 | AM10: =AI10+AI10*AJ10+AI10*AK10-AL10*AK10 -> 1217.9 | AO10: =LN((AM10+AN10)/AM9) -> 0 | AP10: 45302 | AQ10: 1047.7 | AU10: =AQ10+AQ10*AR10+AQ10*AS10-AT10*AS10 -> 1047.7 | AW10: =LN((AU10+AV10)/AU9) -> 0 | AX10: 45302 | AY10: 42.9 | BC10: =AY10+AY10*AZ10+AY10*BA10-BB10*BA10 -> 42.9 | BE10: =LN((BC10+BD10)/BC9) -> 0 | BF10: 45302 | BG10: 154.8 | BK10: =BG10+BG10*BH10+BG10*BI10-BJ10*BI10 -> 154.8 | BM10: =LN((BK10+BL10)/BK9) -> -0.0038684768
B11: 45305 | C11: 12.4 | G11: =C11+C11*D11+C11*E11-F11*E11 -> 12.4 | I11: =LN((G11+H11)/G10) -> 0 | J11: 45305 | K11: 46.5 | O11: =K11+K11*L11+K11*M11-N11*M11 -> 46.5 | Q11: =LN((O11+P11)/O10) -> 0 | R11: 45305 | S11: 286.6 | W11: =S11+S11*T11+S11*U11-V11*U11 -> 286.6 | Y11: =LN((W11+X11)/W10) -> 0 | Z11: 45305 | AA11: 978.8 | AE11: =AA11+AA11*AB11+AA11*AC11-AD11*AC11 -> 978.8 | AG11: =LN((AE11+AF11)/AE10) -> 0.0099595258 | AH11: 45305 | AI11: 1217.9 | AM11: =AI11+AI11*AJ11+AI11*AK11-AL11*AK11 -> 1217.9 | AO11: =LN((AM11+AN11)/AM10) -> 0 | AP11: 45305 | AQ11: 1047.7 | AU11: =AQ11+AQ11*AR11+AQ11*AS11-AT11*AS11 -> 1047.7 | AW11: =LN((AU11+AV11)/AU10) -> 0 | AX11: 45305 | AY11: 42.9 | BC11: =AY11+AY11*AZ11+AY11*BA11-BB11*BA11 -> 42.9 | BE11: =LN((BC11+BD11)/BC10) -> 0 | BF11: 45305 | BG11: 155.2 | BK11: =BG11+BG11*BH11+BG11*BI11-BJ11*BI11 -> 155.2 | BM11: =LN((BK11+BL11)/BK10) -> 0.0025806466
B12: 45306 | C12: 12.4 | G12: =C12+C12*D12+C12*E12-F12*E12 -> 12.4 | I12: =LN((G12+H12)/G11) -> 0 | J12: 45306 | K12: 46.5 | O12: =K12+K12*L12+K12*M12-N12*M12 -> 46.5 | Q12: =LN((O12+P12)/O11) -> 0 | R12: 45306 | S12: 286.6 | W12: =S12+S12*T12+S12*U12-V12*U12 -> 286.6 | Y12: =LN((W12+X12)/W11) -> 0 | Z12: 45306 | AA12: 983.5 | AE12: =AA12+AA12*AB12+AA12*AC12-AD12*AC12 -> 983.5 | AG12: =LN((AE12+AF12)/AE11) -> 0.0047903063 | AH12: 45306 | AI12: 1217.9 | AM12: =AI12+AI12*AJ12+AI12*AK12-AL12*AK12 -> 1217.9 | AO12: =LN((AM12+AN12)/AM11) -> 0 | AP12: 45306 | AQ12: 1047.7 | AU12: =AQ12+AQ12*AR12+AQ12*AS12-AT12*AS12 -> 1047.7 | AW12: =LN((AU12+AV12)/AU11) -> 0 | AX12: 45306 | AY12: 42.9 | BC12: =AY12+AY12*AZ12+AY12*BA12-BB12*BA12 -> 42.9 | BE12: =LN((BC12+BD12)/BC11) -> 0 | BF12: 45306 | BG12: 156.8 | BK12: =BG12+BG12*BH12+BG12*BI12-BJ12*BI12 -> 156.8 | BM12: =LN((BK12+BL12)/BK11) -> 0.0102565
B13: 45307 | C13: 12.4 | G13: =C13+C13*D13+C13*E13-F13*E13 -> 12.4 | I13: =LN((G13+H13)/G12) -> 0 | J13: 45307 | K13: 46.5 | O13: =K13+K13*L13+K13*M13-N13*M13 -> 46.5 | Q13: =LN((O13+P13)/O12) -> 0 | R13: 45307 | S13: 286.6 | W13: =S13+S13*T13+S13*U13-V13*U13 -> 286.6 | Y13: =LN((W13+X13)/W12) -> 0 | Z13: 45307 | AA13: 983 | AE13: =AA13+AA13*AB13+AA13*AC13-AD13*AC13 -> 983 | AG13: =LN((AE13+AF13)/AE12) -> -0.00050851768 | AH13: 45307 | AI13: 1217.9 | AM13: =AI13+AI13*AJ13+AI13*AK13-AL13*AK13 -> 1217.9 | AO13: =LN((AM13+AN13)/AM12) -> 0 | AP13: 45307 | AQ13: 1047.7 | AU13: =AQ13+AQ13*AR13+AQ13*AS13-AT13*AS13 -> 1047.7 | AW13: =LN((AU13+AV13)/AU12) -> 0 | AX13: 45307 | AY13: 42.9 | BC13: =AY13+AY13*AZ13+AY13*BA13-BB13*BA13 -> 42.9 | BE13: =LN((BC13+BD13)/BC12) -> 0 | BF13: 45307 | BG13: 156.3 | BK13: =BG13+BG13*BH13+BG13*BI13-BJ13*BI13 -> 156.3 | BM13: =LN((BK13+BL13)/BK12) -> -0.0031938705
B14: 45308 | C14: 12.4 | G14: =C14+C14*D14+C14*E14-F14*E14 -> 12.4 | I14: =LN((G14+H14)/G13) -> 0 | J14: 45308 | K14: 46.5 | O14: =K14+K14*L14+K14*M14-N14*M14 -> 46.5 | Q14: =LN((O14+P14)/O13) -> 0 | R14: 45308 | S14: 286.6 | W14: =S14+S14*T14+S14*U14-V14*U14 -> 286.6 | Y14: =LN((W14+X14)/W13) -> 0 | Z14: 45308 | AA14: 994.8 | AE14: =AA14+AA14*AB14+AA14*AC14-AD14*AC14 -> 994.8 | AG14: =LN((AE14+AF14)/AE13) -> 0.011932592 | AH14: 45308 | AI14: 1217.9 | AM14: =AI14+AI14*AJ14+AI14*AK14-AL14*AK14 -> 1217.9 | AO14: =LN((AM14+AN14)/AM13) -> 0 | AP14: 45308 | AQ14: 1047.7 | AU14: =AQ14+AQ14*AR14+AQ14*AS14-AT14*AS14 -> 1047.7 | AW14: =LN((AU14+AV14)/AU13) -> 0 | AX14: 45308 | AY14: 42.9 | BC14: =AY14+AY14*AZ14+AY14*BA14-BB14*BA14 -> 42.9 | BE14: =LN((BC14+BD14)/BC13) -> 0 | BF14: 45308 | BG14: 155.2 | BK14: =BG14+BG14*BH14+BG14*BI14-BJ14*BI14 -> 155.2 | BM14: =LN((BK14+BL14)/BK13) -> -0.0070626297
B15: 45309 | C15: 12.4 | G15: =C15+C15*D15+C15*E15-F15*E15 -> 12.4 | I15: =LN((G15+H15)/G14) -> 0 | J15: 45309 | K15: 46.5 | O15: =K15+K15*L15+K15*M15-N15*M15 -> 46.5 | Q15: =LN((O15+P15)/O14) -> 0 | R15: 45309 | S15: 286.6 | W15: =S15+S15*T15+S15*U15-V15*U15 -> 286.6 | Y15: =LN((W15+X15)/W14) -> 0 | Z15: 45309 | AA15: 987.6 | AE15: =AA15+AA15*AB15+AA15*AC15-AD15*AC15 -> 987.6 | AG15: =LN((AE15+AF15)/AE14) -> -0.0072639545 | AH15: 45309 | AI15: 1217.9 | AM15: =AI15+AI15*AJ15+AI15*AK15-AL15*AK15 -> 1217.9 | AO15: =LN((AM15+AN15)/AM14) -> 0 | AP15: 45309 | AQ15: 1047.7 | AU15: =AQ15+AQ15*AR15+AQ15*AS15-AT15*AS15 -> 1047.7 | AW15: =LN((AU15+AV15)/AU14) -> 0 | AX15: 45309 | AY15: 42.9 | BC15: =AY15+AY15*AZ15+AY15*BA15-BB15*BA15 -> 42.9 | BE15: =LN((BC15+BD15)/BC14) -> 0 | BF15: 45309 | BG15: 154.2 | BK15: =BG15+BG15*BH15+BG15*BI15-BJ15*BI15 -> 154.2 | BM15: =LN((BK15+BL15)/BK14) -> -0.0064641466
B16: 45312 | C16: 11.3 | G16: =C16+C16*D16+C16*E16-F16*E16 -> 11.3 | I16: =LN((G16+H16)/G15) -> -0.092893747 | J16: 45312 | K16: 46.5 | O16: =K16+K16*L16+K16*M16-N16*M16 -> 46.5 | Q16: =LN((O16+P16)/O15) -> 0 | R16: 45312 | S16: 286.6 | W16: =S16+S16*T16+S16*U16-V16*U16 -> 286.6 | Y16: =LN((W16+X16)/W15) -> 0 | Z16: 45312 | AA16: 991 | AE16: =AA16+AA16*AB16+AA16*AC16-AD16*AC16 -> 991 | AG16: =LN((AE16+AF16)/AE15) -> 0.0034367769 | AH16: 45312 | AI16: 1217.9 | AM16: =AI16+AI16*AJ16+AI16*AK16-AL16*AK16 -> 1217.9 | AO16: =LN((AM16+AN16)/AM15) -> 0 | AP16: 45312 | AQ16: 982.3 | AU16: =AQ16+AQ16*AR16+AQ16*AS16-AT16*AS16 -> 982.3 | AW16: =LN((AU16+AV16)/AU15) -> -0.064455804 | AX16: 45312 | AY16: 38.7 | BC16: =AY16+AY16*AZ16+AY16*BA16-BB16*BA16 -> 38.7 | BE16: =LN((BC16+BD16)/BC15) -> -0.10303223 | BF16: 45312 | BG16: 154.6 | BK16: =BG16+BG16*BH16+BG16*BI16-BJ16*BI16 -> 154.6 | BM16: =LN((BK16+BL16)/BK15) -> 0.002590675
B17: 45313 | C17: 11.6 | G17: =C17+C17*D17+C17*E17-F17*E17 -> 11.6 | I17: =LN((G17+H17)/G16) -> 0.026202372 | J17: 45313 | K17: 46.5 | O17: =K17+K17*L17+K17*M17-N17*M17 -> 46.5 | Q17: =LN((O17+P17)/O16) -> 0 | R17: 45313 | S17: 286.6 | W17: =S17+S17*T17+S17*U17-V17*U17 -> 286.6 | Y17: =LN((W17+X17)/W16) -> 0 | Z17: 45313 | AA17: 999.2 | AE17: =AA17+AA17*AB17+AA17*AC17-AD17*AC17 -> 999.2 | AG17: =LN((AE17+AF17)/AE16) -> 0.0082404245 | AH17: 45313 | AI17: 1217.9 | AM17: =AI17+AI17*AJ17+AI17*AK17-AL17*AK17 -> 1217.9 | AO17: =LN((AM17+AN17)/AM16) -> 0 | AP17: 45313 | AQ17: 908.7 | AU17: =AQ17+AQ17*AR17+AQ17*AS17-AT17*AS17 -> 908.7 | AW17: =LN((AU17+AV17)/AU16) -> -0.077881754 | AX17: 45313 | AY17: 36.6 | BC17: =AY17+AY17*AZ17+AY17*BA17-BB17*BA17 -> 36.6 | BE17: =LN((BC17+BD17)/BC16) -> -0.05579136 | BF17: 45313 | BG17: 156.8 | BK17: =BG17+BG17*BH17+BG17*BI17-BJ17*BI17 -> 156.8 | BL17: 6 | BM17: =LN((BK17+BL17)/BK16) -> 0.051681317
B18: 45314 | C18: 12.4 | G18: =C18+C18*D18+C18*E18-F18*E18 -> 12.4 | I18: =LN((G18+H18)/G17) -> 0.066691374 | J18: 45314 | K18: 43.9 | O18: =K18+K18*L18+K18*M18-N18*M18 -> 43.9 | Q18: =LN((O18+P18)/O17) -> -0.057537993 | R18: 45314 | S18: 286.6 | W18: =S18+S18*T18+S18*U18-V18*U18 -> 286.6 | Y18: =LN((W18+X18)/W17) -> 0 | Z18: 45314 | AA18: 1009.6 | AE18: =AA18+AA18*AB18+AA18*AC18-AD18*AC18 -> 1009.6 | AG18: =LN((AE18+AF18)/AE17) -> 0.010354533 | AH18: 45314 | AI18: 1217.9 | AM18: =AI18+AI18*AJ18+AI18*AK18-AL18*AK18 -> 1217.9 | AO18: =LN((AM18+AN18)/AM17) -> 0 | AP18: 45314 | AQ18: 840.6 | AU18: =AQ18+AQ18*AR18+AQ18*AS18-AT18*AS18 -> 840.6 | AW18: =LN((AU18+AV18)/AU17) -> -0.077899084 | AX18: 45314 | AY18: 36.6 | BC18: =AY18+AY18*AZ18+AY18*BA18-BB18*BA18 -> 36.6 | BE18: =LN((BC18+BD18)/BC17) -> 0 | BF18: 45314 | BG18: 155.3 | BK18: =BG18+BG18*BH18+BG18*BI18-BJ18*BI18 -> 155.3 | BM18: =LN((BK18+BL18)/BK17) -> -0.0096123778
B19: 45315 | C19: 12.2 | G19: =C19+C19*D19+C19*E19-F19*E19 -> 12.2 | I19: =LN((G19+H19)/G18) -> -0.016260521 | J19: 45315 | K19: 42.4 | O19: =K19+K19*L19+K19*M19-N19*M19 -> 42.4 | Q19: =LN((O19+P19)/O18) -> -0.034765958 | R19: 45315 | S19: 286.6 | W19: =S19+S19*T19+S19*U19-V19*U19 -> 286.6 | Y19: =LN((W19+X19)/W18) -> 0 | Z19: 45315 | AA19: 1009.4 | AE19: =AA19+AA19*AB19+AA19*AC19-AD19*AC19 -> 1009.4 | AG19: =LN((AE19+AF19)/AE18) -> -0.00019811788 | AH19: 45315 | AI19: 1217.9 | AM19: =AI19+AI19*AJ19+AI19*AK19-AL19*AK19 -> 1217.9 | AO19: =LN((AM19+AN19)/AM18) -> 0 | AP19: 45315 | AQ19: 781.6 | AU19: =AQ19+AQ19*AR19+AQ19*AS19-AT19*AS19 -> 781.6 | AW19: =LN((AU19+AV19)/AU18) -> -0.072772822 | AX19: 45315 | AY19: 35.1 | BC19: =AY19+AY19*AZ19+AY19*BA19-BB19*BA19 -> 35.1 | BE19: =LN((BC19+BD19)/BC18) -> -0.04184711 | BF19: 45315 | BG19: 155 | BK19: =BG19+BG19*BH19+BG19*BI19-BJ19*BI19 -> 155 | BM19: =LN((BK19+BL19)/BK18) -> -0.0019336132
B20: 45316 | C20: 11.9 | G20: =C20+C20*D20+C20*E20-F20*E20 -> 11.9 | I20: =LN((G20+H20)/G19) -> -0.024897552 | J20: 45316 | K20: 40.6 | O20: =K20+K20*L20+K20*M20-N20*M20 -> 40.6 | Q20: =LN((O20+P20)/O19) -> -0.043380296 | R20: 45316 | S20: 286.6 | W20: =S20+S20*T20+S20*U20-V20*U20 -> 286.6 | Y20: =LN((W20+X20)/W19) -> 0 | Z20: 45316 | AA20: 1007.7 | AE20: =AA20+AA20*AB20+AA20*AC20-AD20*AC20 -> 1007.7 | AG20: =LN((AE20+AF20)/AE19) -> -0.0016855886 | AH20: 45316 | AI20: 1217.9 | AM20: =AI20+AI20*AJ20+AI20*AK20-AL20*AK20 -> 1217.9 | AO20: =LN((AM20+AN20)/AM19) -> 0 | AP20: 45316 | AQ20: 764.9 | AU20: =AQ20+AQ20*AR20+AQ20*AS20-AT20*AS20 -> 764.9 | AW20: =LN((AU20+AV20)/AU19) -> -0.021597994 | AX20: 45316 | AY20: 35.1 | BC20: =AY20+AY20*AZ20+AY20*BA20-BB20*BA20 -> 35.1 | BE20: =LN((BC20+BD20)/BC19) -> 0 | BF20: 45316 | BG20: 154.7 | BK20: =BG20+BG20*BH20+BG20*BI20-BJ20*BI20 -> 154.7 | BM20: =LN((BK20+BL20)/BK19) -> -0.0019373593
B21: 45319 | C21: 11.9 | G21: =C21+C21*D21+C21*E21-F21*E21 -> 11.9 | I21: =LN((G21+H21)/G20) -> 0 | J21: 45319 | K21: 38.4 | O21: =K21+K21*L21+K21*M21-N21*M21 -> 38.4 | Q21: =LN((O21+P21)/O20) -> -0.055710607 | R21: 45319 | S21: 286.6 | W21: =S21+S21*T21+S21*U21-V21*U21 -> 286.6 | Y21: =LN((W21+X21)/W20) -> 0 | Z21: 45319 | AA21: 1000.4 | AE21: =AA21+AA21*AB21+AA21*AC21-AD21*AC21 -> 1000.4 | AG21: =LN((AE21+AF21)/AE20) -> -0.0072705863 | AH21: 45319 | AI21: 1217.9 | AM21: =AI21+AI21*AJ21+AI21*AK21-AL21*AK21 -> 1217.9 | AO21: =LN((AM21+AN21)/AM20) -> 0 | AP21: 45319 | AQ21: 713.3 | AU21: =AQ21+AQ21*AR21+AQ21*AS21-AT21*AS21 -> 713.3 | AW21: =LN((AU21+AV21)/AU20) -> -0.069843017 | AX21: 45319 | AY21: 32.6 | BC21: =AY21+AY21*AZ21+AY21*BA21-BB21*BA21 -> 32.6 | BE21: =LN((BC21+BD21)/BC20) -> -0.073888842 | BF21: 45319 | BG21: 155.1 | BK21: =BG21+BG21*BH21+BG21*BI21-BJ21*BI21 -> 155.1 | BM21: =LN((BK21+BL21)/BK20) -> 0.0025823126
B22: 45320 | C22: 12.1 | G22: =C22+C22*D22+C22*E22-F22*E22 -> 12.1 | I22: =LN((G22+H22)/G21) -> 0.016667052 | J22: 45320 | K22: 38 | O22: =K22+K22*L22+K22*M22-N22*M22 -> 38 | Q22: =LN((O22+P22)/O21) -> -0.0104713 | R22: 45320 | S22: 286.6 | W22: =S22+S22*T22+S22*U22-V22*U22 -> 286.6 | Y22: =LN((W22+X22)/W21) -> 0 | Z22: 45320 | AA22: 1000.4 | AE22: =AA22+AA22*AB22+AA22*AC22-AD22*AC22 -> 1000.4 | AG22: =LN((AE22+AF22)/AE21) -> 0 | AH22: 45320 | AI22: 1217.9 | AM22: =AI22+AI22*AJ22+AI22*AK22-AL22*AK22 -> 1217.9 | AO22: =LN((AM22+AN22)/AM21) -> 0 | AP22: 45320 | AQ22: 702.2 | AU22: =AQ22+AQ22*AR22+AQ22*AS22-AT22*AS22 -> 702.2 | AW22: =LN((AU22+AV22)/AU21) -> -0.015683826 | AX22: 45320 | AY22: 33 | BC22: =AY22+AY22*AZ22+AY22*BA22-BB22*BA22 -> 33 | BE22: =LN((BC22+BD22)/BC21) -> 0.012195273 | BF22: 45320 | BG22: 153.8 | BK22: =BG22+BG22*BH22+BG22*BI22-BJ22*BI22 -> 153.8 | BM22: =LN((BK22+BL22)/BK21) -> -0.0084170131
B23: 45321 | C23: 12 | G23: =C23+C23*D23+C23*E23-F23*E23 -> 12 | I23: =LN((G23+H23)/G22) -> -0.0082988028 | J23: 45321 | K23: 38.9 | O23: =K23+K23*L23+K23*M23-N23*M23 -> 38.9 | Q23: =LN((O23+P23)/O22) -> 0.023408091 | R23: 45321 | S23: 286.6 | W23: =S23+S23*T23+S23*U23-V23*U23 -> 286.6 | Y23: =LN((W23+X23)/W22) -> 0 | Z23: 45321 | AA23: 992 | AE23: =AA23+AA23*AB23+AA23*AC23-AD23*AC23 -> 992 | AG23: =LN((AE23+AF23)/AE22) -> -0.0084320917 | AH23: 45321 | AI23: 1217.9 | AM23: =AI23+AI23*AJ23+AI23*AK23-AL23*AK23 -> 1217.9 | AO23: =LN((AM23+AN23)/AM22) -> 0 | AP23: 45321 | AQ23: 754.8 | AU23: =AQ23+AQ23*AR23+AQ23*AS23-AT23*AS23 -> 754.8 | AW23: =LN((AU23+AV23)/AU22) -> 0.07223455 | AX23: 45321 | AY23: 34.1 | BC23: =AY23+AY23*AZ23+AY23*BA23-BB23*BA23 -> 34.1 | BE23: =LN((BC23+BD23)/BC22) -> 0.032789823 | BF23: 45321 | BG23: 154 | BK23: =BG23+BG23*BH23+BG23*BI23-BJ23*BI23 -> 154 | BM23: =LN((BK23+BL23)/BK22) -> 0.0012995453
B24: 45322 | C24: 11.9 | G24: =C24+C24*D24+C24*E24-F24*E24 -> 11.9 | I24: =LN((G24+H24)/G23) -> -0.0083682497 | J24: 45322 | K24: 38.7 | O24: =K24+K24*L24+K24*M24-N24*M24 -> 38.7 | Q24: =LN((O24+P24)/O23) -> -0.0051546506 | R24: 45322 | S24: 286.6 | W24: =S24+S24*T24+S24*U24-V24*U24 -> 286.6 | Y24: =LN((W24+X24)/W23) -> 0 | Z24: 45322 | AA24: 986.2 | AE24: =AA24+AA24*AB24+AA24*AC24-AD24*AC24 -> 986.2 | AG24: =LN((AE24+AF24)/AE23) -> -0.0058639335 | AH24: 45322 | AI24: 1217.9 | AM24: =AI24+AI24*AJ24+AI24*AK24-AL24*AK24 -> 1217.9 | AO24: =LN((AM24+AN24)/AM23) -> 0 | AP24: 45322 | AQ24: 752.8 | AU24: =AQ24+AQ24*AR24+AQ24*AS24-AT24*AS24 -> 752.8 | AW24: =LN((AU24+AV24)/AU23) -> -0.0026532252 | AX24: 45322 | AY24: 33.5 | BC24: =AY24+AY24*AZ24+AY24*BA24-BB24*BA24 -> 33.5 | BE24: =LN((BC24+BD24)/BC23) -> -0.017751945 | BF24: 45322 | BG24: 152.7 | BK24: =BG24+BG24*BH24+BG24*BI24-BJ24*BI24 -> 152.7 | BM24: =LN((BK24+BL24)/BK23) -> -0.0084773902
B25: 45323 | C25: 12 | G25: =C25+C25*D25+C25*E25-F25*E25 -> 12 | I25: =LN((G25+H25)/G24) -> 0.0083682497 | J25: 45323 | K25: 41.4 | O25: =K25+K25*L25+K25*M25-N25*M25 -> 41.4 | Q25: =LN((O25+P25)/O24) -> 0.067441281 | R25: 45323 | S25: 286.6 | W25: =S25+S25*T25+S25*U25-V25*U25 -> 286.6 | Y25: =LN((W25+X25)/W24) -> 0 | Z25: 45323 | AA25: 991.9 | AE25: =AA25+AA25*AB25+AA25*AC25-AD25*AC25 -> 991.9 | AG25: =LN((AE25+AF25)/AE24) -> 0.005763122 | AH25: 45323 | AI25: 1217.9 | AM25: =AI25+AI25*AJ25+AI25*AK25-AL25*AK25 -> 1217.9 | AO25: =LN((AM25+AN25)/AM24) -> 0 | AP25: 45323 | AQ25: 757.3 | AU25: =AQ25+AQ25*AR25+AQ25*AS25-AT25*AS25 -> 757.3 | AW25: =LN((AU25+AV25)/AU24) -> 0.0059598878 | AX25: 45323 | AY25: 34.9 | BC25: =AY25+AY25*AZ25+AY25*BA25-BB25*BA25 -> 34.9 | BE25: =LN((BC25+BD25)/BC24) -> 0.04094139 | BF25: 45323 | BG25: 152 | BK25: =BG25+BG25*BH25+BG25*BI25-BJ25*BI25 -> 152 | BM25: =LN((BK25+BL25)/BK24) -> -0.0045946914
B26: 45326 | C26: 12.1 | G26: =C26+C26*D26+C26*E26-F26*E26 -> 12.1 | I26: =LN((G26+H26)/G25) -> 0.0082988028 | J26: 45326 | K26: 42.3 | O26: =K26+K26*L26+K26*M26-N26*M26 -> 42.3 | Q26: =LN((O26+P26)/O25) -> 0.021506205 | R26: 45326 | S26: 286.6 | W26: =S26+S26*T26+S26*U26-V26*U26 -> 286.6 | Y26: =LN((W26+X26)/W25) -> 0 | Z26: 45326 | AA26: 999.5 | AE26: =AA26+AA26*AB26+AA26*AC26-AD26*AC26 -> 999.5 | AG26: =LN((AE26+AF26)/AE25) -> 0.0076328582 | AH26: 45326 | AI26: 1217.9 | AM26: =AI26+AI26*AJ26+AI26*AK26-AL26*AK26 -> 1217.9 | AO26: =LN((AM26+AN26)/AM25) -> 0 | AP26: 45326 | AQ26: 801.4 | AU26: =AQ26+AQ26*AR26+AQ26*AS26-AT26*AS26 -> 801.4 | AW26: =LN((AU26+AV26)/AU25) -> 0.056600722 | AX26: 45326 | AY26: 36.8 | BC26: =AY26+AY26*AZ26+AY26*BA26-BB26*BA26 -> 36.8 | BE26: =LN((BC26+BD26)/BC25) -> 0.053011016 | BF26: 45326 | BG26: 152.8 | BK26: =BG26+BG26*BH26+BG26*BI26-BJ26*BI26 -> 152.8 | BM26: =LN((BK26+BL26)/BK25) -> 0.0052493559
B27: 45327 | C27: 12.4 | G27: =C27+C27*D27+C27*E27-F27*E27 -> 12.4 | I27: =LN((G27+H27)/G26) -> 0.02449102 | J27: 45327 | K27: 43.5 | O27: =K27+K27*L27+K27*M27-N27*M27 -> 43.5 | Q27: =LN((O27+P27)/O26) -> 0.027973852 | R27: 45327 | S27: 286.6 | W27: =S27+S27*T27+S27*U27-V27*U27 -> 286.6 | Y27: =LN((W27+X27)/W26) -> 0 | Z27: 45327 | AA27: 1001.7 | AE27: =AA27+AA27*AB27+AA27*AC27-AD27*AC27 -> 1001.7 | AG27: =LN((AE27+AF27)/AE26) -> 0.0021986817 | AH27: 45327 | AI27: 1217.9 | AM27: =AI27+AI27*AJ27+AI27*AK27-AL27*AK27 -> 1217.9 | AO27: =LN((AM27+AN27)/AM26) -> 0 | AP27: 45327 | AQ27: 844.9 | AU27: =AQ27+AQ27*AR27+AQ27*AS27-AT27*AS27 -> 844.9 | AW27: =LN((AU27+AV27)/AU26) -> 0.052858079 | AX27: 45327 | AY27: 36.7 | BC27: =AY27+AY27*AZ27+AY27*BA27-BB27*BA27 -> 36.7 | BE27: =LN((BC27+BD27)/BC26) -> -0.0027210901 | BF27: 45327 | BG27: 153.4 | BK27: =BG27+BG27*BH27+BG27*BI27-BJ27*BI27 -> 153.4 | BM27: =LN((BK27+BL27)/BK26) -> 0.0039190122
B28: 45328 | C28: 12.2 | G28: =C28+C28*D28+C28*E28-F28*E28 -> 12.2 | I28: =LN((G28+H28)/G27) -> -0.016260521 | J28: 45328 | K28: 42.7 | O28: =K28+K28*L28+K28*M28-N28*M28 -> 42.7 | Q28: =LN((O28+P28)/O27) -> -0.018562018 | R28: 45328 | S28: 286.6 | W28: =S28+S28*T28+S28*U28-V28*U28 -> 286.6 | Y28: =LN((W28+X28)/W27) -> 0 | Z28: 45328 | AA28: 999.8 | AE28: =AA28+AA28*AB28+AA28*AC28-AD28*AC28 -> 999.8 | AG28: =LN((AE28+AF28)/AE27) -> -0.0018985766 | AH28: 45328 | AI28: 1217.9 | AM28: =AI28+AI28*AJ28+AI28*AK28-AL28*AK28 -> 1217.9 | AO28: =LN((AM28+AN28)/AM27) -> 0 | AP28: 45328 | AQ28: 843.5 | AU28: =AQ28+AQ28*AR28+AQ28*AS28-AT28*AS28 -> 843.5 | AW28: =LN((AU28+AV28)/AU27) -> -0.0016583752 | AX28: 45328 | AY28: 37.3 | BC28: =AY28+AY28*AZ28+AY28*BA28-BB28*BA28 -> 37.3 | BE28: =LN((BC28+BD28)/BC27) -> 0.016216572 | BF28: 45328 | BG28: 152.4 | BK28: =BG28+BG28*BH28+BG28*BI28-BJ28*BI28 -> 152.4 | BM28: =LN((BK28+BL28)/BK27) -> -0.0065402457
B29: 45329 | C29: 12.2 | G29: =C29+C29*D29+C29*E29-F29*E29 -> 12.2 | I29: =LN((G29+H29)/G28) -> 0 | J29: 45329 | K29: 42.6 | O29: =K29+K29*L29+K29*M29-N29*M29 -> 42.6 | Q29: =LN((O29+P29)/O28) -> -0.002344667 | R29: 45329 | S29: 286.6 | W29: =S29+S29*T29+S29*U29-V29*U29 -> 286.6 | Y29: =LN((W29+X29)/W28) -> 0 | Z29: 45329 | AA29: 989.8 | AE29: =AA29+AA29*AB29+AA29*AC29-AD29*AC29 -> 989.8 | AG29: =LN((AE29+AF29)/AE28) -> -0.010052356 | AH29: 45329 | AI29: 1141.8 | AM29: =AI29+AI29*AJ29+AI29*AK29-AL29*AK29 -> 1141.8 | AO29: =LN((AM29+AN29)/AM28) -> -0.0645221 | AP29: 45329 | AQ29: 822.5 | AU29: =AQ29+AQ29*AR29+AQ29*AS29-AT29*AS29 -> 822.5 | AW29: =LN((AU29+AV29)/AU28) -> -0.025211419 | AX29: 45329 | AY29: 41 | BC29: =AY29+AY29*AZ29+AY29*BA29-BB29*BA29 -> 41 | BE29: =LN((BC29+BD29)/BC28) -> 0.09457874 | BF29: 45329 | BG29: 152 | BK29: =BG29+BG29*BH29+BG29*BI29-BJ29*BI29 -> 152 | BM29: =LN((BK29+BL29)/BK28) -> -0.0026281224
... B36: 45340 | C36: 12.7 | G36: =C36+C36*D36+C36*E36-F36*E36 -> 12.7 | I36: =LN((G36+H36)/G35) -> 0.0079051795 | J36: 45340 | K36: 41 | O36: =K36+K36*L36+K36*M36-N36*M36 -> 41 | Q36: =LN((O36+P36)/O35) -> -0.019324273 | R36: 45340 | S36: 286.6 | W36: =S36+S36*T36+S36*U36-V36*U36 -> 286.6 | Y36: =LN((W36+X36)/W35) -> 0 | Z36: 45340 | AA36: 1001.3 | AE36: =AA36+AA36*AB36+AA36*AC36-AD36*AC36 -> 1001.3 | AG36: =LN((AE36+AF36)/AE35) -> 0.00089923571 | AH36: 45340 | AI36: 977.9 | AM36: =AI36+AI36*AJ36+AI36*AK36-AL36*AK36 -> 977.9 | AO36: =LN((AM36+AN36)/AM35) -> -0.0071326979 | AP36: 45340 | AQ36: 778 | AU36: =AQ36+AQ36*AR36+AQ36*AS36-AT36*AS36 -> 778 | AW36: =LN((AU36+AV36)/AU35) -> 0.0015436072 | AX36: 45340 | AY36: 38.1 | BC36: =AY36+AY36*AZ36+AY36*BA36-BB36*BA36 -> 38.1 | BE36: =LN((BC36+BD36)/BC35) -> 0.015873349 | BF36: 45340 | BG36: 150.5 | BK36: =BG36+BG36*BH36+BG36*BI36-BJ36*BI36 -> 150.5 | BM36: =LN((BK36+BL36)/BK35) -> 0.0019953449
B37: 45341 | C37: 13 | G37: =C37+C37*D37+C37*E37-F37*E37 -> 13 | I37: =LN((G37+H37)/G36) -> 0.023347364 | J37: 45341 | K37: 40.6 | O37: =K37+K37*L37+K37*M37-N37*M37 -> 40.6 | Q37: =LN((O37+P37)/O36) -> -0.0098040001 | R37: 45341 | S37: 286.6 | W37: =S37+S37*T37+S37*U37-V37*U37 -> 286.6 | Y37: =LN((W37+X37)/W36) -> 0 | Z37: 45341 | AA37: 1000 | AE37: =AA37+AA37*AB37+AA37*AC37-AD37*AC37 -> 1000 | AG37: =LN((AE37+AF37)/AE36) -> -0.0012991557 | AH37: 45341 | AI37: 977.1 | AM37: =AI37+AI37*AJ37+AI37*AK37-AL37*AK37 -> 977.1 | AO37: =LN((AM37+AN37)/AM36) -> -0.00081841437 | AP37: 45341 | AQ37: 760.9 | AU37: =AQ37+AQ37*AR37+AQ37*AS37-AT37*AS37 -> 760.9 | AW37: =LN((AU37+AV37)/AU36) -> -0.022224581 | AX37: 45341 | AY37: 38.1 | BC37: =AY37+AY37*AZ37+AY37*BA37-BB37*BA37 -> 38.1 | BD37: 1 | BE37: =LN((BC37+BD37)/BC36) -> 0.025908185 | BF37: 45341 | BG37: 150.2 | BK37: =BG37+BG37*BH37+BG37*BI37-BJ37*BI37 -> 150.2 | BM37: =LN((BK37+BL37)/BK36) -> -0.0019953449
B38: 45342 | C38: 13.1 | G38: =C38+C38*D38+C38*E38-F38*E38 -> 13.1 | I38: =LN((G38+H38)/G37) -> 0.0076628727 | J38: 45342 | K38: 40.6 | O38: =K38+K38*L38+K38*M38-N38*M38 -> 40.6 | Q38: =LN((O38+P38)/O37) -> 0 | R38: 45342 | S38: 286.6 | W38: =S38+S38*T38+S38*U38-V38*U38 -> 286.6 | Y38: =LN((W38+X38)/W37) -> 0 | Z38: 45342 | AA38: 988 | AE38: =AA38+AA38*AB38+AA38*AC38-AD38*AC38 -> 988 | AG38: =LN((AE38+AF38)/AE37) -> -0.012072581 | AH38: 45342 | AI38: 969.3 | AM38: =AI38+AI38*AJ38+AI38*AK38-AL38*AK38 -> 969.3 | AO38: =LN((AM38+AN38)/AM37) -> -0.0080148395 | AP38: 45342 | AQ38: 761.3 | AU38: =AQ38+AQ38*AR38+AQ38*AS38-AT38*AS38 -> 761.3 | AW38: =LN((AU38+AV38)/AU37) -> 0.00052555513 | AX38: 45342 | AY38: 37.3 | BC38: =AY38+AY38*AZ38+AY38*BA38-BB38*BA38 -> 37.3 | BE38: =LN((BC38+BD38)/BC37) -> -0.021220955 | BF38: 45342 | BG38: 150 | BK38: =BG38+BG38*BH38+BG38*BI38-BJ38*BI38 -> 150 | BM38: =LN((BK38+BL38)/BK37) -> -0.0013324452
B39: 45344 | C39: 13.1 | G39: =C39+C39*D39+C39*E39-F39*E39 -> 13.1 | I39: =LN((G39+H39)/G38) -> 0 | J39: 45344 | K39: 40.2 | O39: =K39+K39*L39+K39*M39-N39*M39 -> 40.2 | Q39: =LN((O39+P39)/O38) -> -0.009901071 | R39: 45344 | S39: 286.6 | W39: =S39+S39*T39+S39*U39-V39*U39 -> 286.6 | Y39: =LN((W39+X39)/W38) -> 0 | Z39: 45344 | AA39: 987.6 | AE39: =AA39+AA39*AB39+AA39*AC39-AD39*AC39 -> 987.6 | AG39: =LN((AE39+AF39)/AE38) -> -0.00040494028 | AH39: 45344 | AI39: 967.4 | AM39: =AI39+AI39*AJ39+AI39*AK39-AL39*AK39 -> 967.4 | AO39: =LN((AM39+AN39)/AM38) -> -0.0019621011 | AP39: 45344 | AQ39: 760.8 | AU39: =AQ39+AQ39*AR39+AQ39*AS39-AT39*AS39 -> 760.8 | AW39: =LN((AU39+AV39)/AU38) -> -0.00065698708 | AX39: 45344 | AY39: 37 | BC39: =AY39+AY39*AZ39+AY39*BA39-BB39*BA39 -> 37 | BE39: =LN((BC39+BD39)/BC38) -> -0.008075414 | BF39: 45344 | BG39: 149.6 | BK39: =BG39+BG39*BH39+BG39*BI39-BJ39*BI39 -> 149.6 | BM39: =LN((BK39+BL39)/BK38) -> -0.0026702286
B40: 45347 | C40: 13 | G40: =C40+C40*D40+C40*E40-F40*E40 -> 13 | I40: =LN((G40+H40)/G39) -> -0.0076628727 | J40: 45347 | K40: 40 | O40: =K40+K40*L40+K40*M40-N40*M40 -> 40 | Q40: =LN((O40+P40)/O39) -> -0.0049875415 | R40: 45347 | S40: 286.6 | W40: =S40+S40*T40+S40*U40-V40*U40 -> 286.6 | Y40: =LN((W40+X40)/W39) -> 0 | Z40: 45347 | AA40: 979.8 | AE40: =AA40+AA40*AB40+AA40*AC40-AD40*AC40 -> 979.8 | AG40: =LN((AE40+AF40)/AE39) -> -0.0079292883 | AH40: 45347 | AI40: 958.8 | AM40: =AI40+AI40*AJ40+AI40*AK40-AL40*AK40 -> 958.8 | AO40: =LN((AM40+AN40)/AM39) -> -0.0089295578 | AP40: 45347 | AQ40: 753 | AU40: =AQ40+AQ40*AR40+AQ40*AS40-AT40*AS40 -> 753 | AW40: =LN((AU40+AV40)/AU39) -> -0.010305283 | AX40: 45347 | AY40: 36.7 | BC40: =AY40+AY40*AZ40+AY40*BA40-BB40*BA40 -> 36.7 | BE40: =LN((BC40+BD40)/BC39) -> -0.0081411576 | BF40: 45347 | BG40: 149.6 | BK40: =BG40+BG40*BH40+BG40*BI40-BJ40*BI40 -> 149.6 | BM40: =LN((BK40+BL40)/BK39) -> 0
B41: 45349 | C41: 13 | G41: =C41+C41*D41+C41*E41-F41*E41 -> 13 | I41: =LN((G41+H41)/G40) -> 0 | J41: 45349 | K41: 40.1 | O41: =K41+K41*L41+K41*M41-N41*M41 -> 40.1 | Q41: =LN((O41+P41)/O40) -> 0.0024968802 | R41: 45349 | S41: 286.6 | W41: =S41+S41*T41+S41*U41-V41*U41 -> 286.6 | Y41: =LN((W41+X41)/W40) -> 0 | Z41: 45349 | AA41: 999.8 | AE41: =AA41+AA41*AB41+AA41*AC41-AD41*AC41 -> 999.8 | AG41: =LN((AE41+AF41)/AE40) -> 0.02020679 | AH41: 45349 | AI41: 945.6 | AM41: =AI41+AI41*AJ41+AI41*AK41-AL41*AK41 -> 945.6 | AO41: =LN((AM41+AN41)/AM40) -> -0.013862856 | AP41: 45349 | AQ41: 750.3 | AU41: =AQ41+AQ41*AR41+AQ41*AS41-AT41*AS41 -> 750.3 | AW41: =LN((AU41+AV41)/AU40) -> -0.0035921012 | AX41: 45349 | AY41: 36.6 | BC41: =AY41+AY41*AZ41+AY41*BA41-BB41*BA41 -> 36.6 | BE41: =LN((BC41+BD41)/BC40) -> -0.0027285147 | BF41: 45349 | BG41: 146.2 | BK41: =BG41+BG41*BH41+BG41*BI41-BJ41*BI41 -> 146.2 | BM41: =LN((BK41+BL41)/BK40) -> -0.022989518
B42: 45350 | C42: 13 | G42: =C42+C42*D42+C42*E42-F42*E42 -> 13 | I42: =LN((G42+H42)/G41) -> 0 | J42: 45350 | K42: 40 | O42: =K42+K42*L42+K42*M42-N42*M42 -> 40 | Q42: =LN((O42+P42)/O41) -> -0.0024968802 | R42: 45350 | S42: 286.6 | W42: =S42+S42*T42+S42*U42-V42*U42 -> 286.6 | Y42: =LN((W42+X42)/W41) -> 0 | Z42: 45350 | AA42: 994.3 | AE42: =AA42+AA42*AB42+AA42*AC42-AD42*AC42 -> 994.3 | AG42: =LN((AE42+AF42)/AE41) -> -0.005516287 | AH42: 45350 | AI42: 951.8 | AM42: =AI42+AI42*AJ42+AI42*AK42-AL42*AK42 -> 951.8 | AO42: =LN((AM42+AN42)/AM41) -> 0.006535282 | AP42: 45350 | AQ42: 748.2 | AU42: =AQ42+AQ42*AR42+AQ42*AS42-AT42*AS42 -> 748.2 | AW42: =LN((AU42+AV42)/AU41) -> -0.0028028046 | AX42: 45350 | AY42: 36.9 | BC42: =AY42+AY42*AZ42+AY42*BA42-BB42*BA42 -> 36.9 | BE42: =LN((BC42+BD42)/BC41) -> 0.0081633106 | BF42: 45350 | BG42: 145.8 | BK42: =BG42+BG42*BH42+BG42*BI42-BJ42*BI42 -> 145.8 | BM42: =LN((BK42+BL42)/BK41) -> -0.0027397277
B43: 45351 | C43: 13.1 | G43: =C43+C43*D43+C43*E43-F43*E43 -> 13.1 | I43: =LN((G43+H43)/G42) -> 0.0076628727 | J43: 45351 | K43: 39.8 | O43: =K43+K43*L43+K43*M43-N43*M43 -> 39.8 | Q43: =LN((O43+P43)/O42) -> -0.0050125418 | R43: 45351 | S43: 286.6 | W43: =S43+S43*T43+S43*U43-V43*U43 -> 286.6 | Y43: =LN((W43+X43)/W42) -> 0 | Z43: 45351 | AA43: 980.5 | AE43: =AA43+AA43*AB43+AA43*AC43-AD43*AC43 -> 980.5 | AG43: =LN((AE43+AF43)/AE42) -> -0.013976326 | AH43: 45351 | AI43: 943.6 | AM43: =AI43+AI43*AJ43+AI43*AK43-AL43*AK43 -> 943.6 | AO43: =LN((AM43+AN43)/AM42) -> -0.0086525812 | AP43: 45351 | AQ43: 745.5 | AU43: =AQ43+AQ43*AR43+AQ43*AS43-AT43*AS43 -> 745.5 | AW43: =LN((AU43+AV43)/AU42) -> -0.0036151877 | AX43: 45351 | AY43: 36.7 | BC43: =AY43+AY43*AZ43+AY43*BA43-BB43*BA43 -> 36.7 | BE43: =LN((BC43+BD43)/BC42) -> -0.005434796 | BF43: 45351 | BG43: 145.2 | BK43: =BG43+BG43*BH43+BG43*BI43-BJ43*BI43 -> 145.2 | BM43: =LN((BK43+BL43)/BK42) -> -0.0041237172
B44: 45354 | C44: 12.9 | G44: =C44+C44*D44+C44*E44-F44*E44 -> 12.9 | I44: =LN((G44+H44)/G43) -> -0.015384919 | J44: 45354 | K44: 39.4 | O44: =K44+K44*L44+K44*M44-N44*M44 -> 39.4 | Q44: =LN((O44+P44)/O43) -> -0.010101096 | R44: 45354 | S44: 261.6 | W44: =S44+S44*T44+S44*U44-V44*U44 -> 261.6 | X44: 12.5 | Y44: =LN((W44+X44)/W43) -> -0.044594512 | Z44: 45354 | AA44: 978.1 | AE44: =AA44+AA44*AB44+AA44*AC44-AD44*AC44 -> 978.1 | AG44: =LN((AE44+AF44)/AE43) -> -0.0024507313 | AH44: 45354 | AI44: 945.6 | AM44: =AI44+AI44*AJ44+AI44*AK44-AL44*AK44 -> 945.6 | AO44: =LN((AM44+AN44)/AM43) -> 0.0021172991 | AP44: 45354 | AQ44: 761.2 | AU44: =AQ44+AQ44*AR44+AQ44*AS44-AT44*AS44 -> 761.2 | AW44: =LN((AU44+AV44)/AU43) -> 0.020841001 | AX44: 45354 | AY44: 36.7 | BC44: =AY44+AY44*AZ44+AY44*BA44-BB44*BA44 -> 36.7 | BE44: =LN((BC44+BD44)/BC43) -> 0 | BF44: 45354 | BG44: 144.3 | BK44: =BG44+BG44*BH44+BG44*BI44-BJ44*BI44 -> 144.3 | BM44: =LN((BK44+BL44)/BK43) -> -0.0062176366
B45: 45355 | C45: 13 | G45: =C45+C45*D45+C45*E45-F45*E45 -> 13 | I45: =LN((G45+H45)/G44) -> 0.0077220461 | J45: 45355 | K45: 39 | O45: =K45+K45*L45+K45*M45-N45*M45 -> 39 | Q45: =LN((O45+P45)/O44) -> -0.01020417 | R45: 45355 | S45: 257.2 | W45: =S45+S45*T45+S45*U45-V45*U45 -> 257.2 | Y45: =LN((W45+X45)/W44) -> -0.016962627 | Z45: 45355 | AA45: 986.9 | AE45: =AA45+AA45*AB45+AA45*AC45-AD45*AC45 -> 986.9 | AG45: =LN((AE45+AF45)/AE44) -> 0.0089568029 | AH45: 45355 | AI45: 940.2 | AM45: =AI45+AI45*AJ45+AI45*AK45-AL45*AK45 -> 940.2 | AO45: =LN((AM45+AN45)/AM44) -> -0.0057270281 | AP45: 45355 | AQ45: 751.4 | AU45: =AQ45+AQ45*AR45+AQ45*AS45-AT45*AS45 -> 751.4 | AW45: =LN((AU45+AV45)/AU44) -> -0.012958002 | AX45: 45355 | AY45: 36 | BC45: =AY45+AY45*AZ45+AY45*BA45-BB45*BA45 -> 36 | BE45: =LN((BC45+BD45)/BC44) -> -0.019257817 | BF45: 45355 | BG45: 146.1 | BK45: =BG45+BG45*BH45+BG45*BI45-BJ45*BI45 -> 146.1 | BM45: =LN((BK45+BL45)/BK44) -> 0.012396853
B46: 45356 | C46: 12.7 | G46: =C46+C46*D46+C46*E46-F46*E46 -> 12.7 | I46: =LN((G46+H46)/G45) -> -0.023347364 | J46: 45356 | K46: 39 | O46: =K46+K46*L46+K46*M46-N46*M46 -> 39 | Q46: =LN((O46+P46)/O45) -> 0 | R46: 45356 | S46: 252.6 | W46: =S46+S46*T46+S46*U46-V46*U46 -> 252.6 | Y46: =LN((W46+X46)/W45) -> -0.018046782 | Z46: 45356 | AA46: 989.5 | AE46: =AA46+AA46*AB46+AA46*AC46-AD46*AC46 -> 989.5 | AG46: =LN((AE46+AF46)/AE45) -> 0.0026310479 | AH46: 45356 | AI46: 932.2 | AM46: =AI46+AI46*AJ46+AI46*AK46-AL46*AK46 -> 932.2 | AO46: =LN((AM46+AN46)/AM45) -> -0.0085452347 | AP46: 45356 | AQ46: 741.8 | AU46: =AQ46+AQ46*AR46+AQ46*AS46-AT46*AS46 -> 741.8 | AW46: =LN((AU46+AV46)/AU45) -> -0.012858468 | AX46: 45356 | AY46: 35.8 | BC46: =AY46+AY46*AZ46+AY46*BA46-BB46*BA46 -> 35.8 | BE46: =LN((BC46+BD46)/BC45) -> -0.005571045 | BF46: 45356 | BG46: 151.2 | BK46: =BG46+BG46*BH46+BG46*BI46-BJ46*BI46 -> 151.2 | BM46: =LN((BK46+BL46)/BK45) -> 0.034312145
...

Sheet DSEX Data
B2: Date | C2: DSEX Value | D2: Average DSEX Value | E2: Change in DSEX Value | G2: Quarter | H2: Average DSEX Value | I2: Change in DSEX Value
B3: 45292 | C3: 6242.87 | G3: Q4 2024 | H3: =D193 -> 5243.632
B4: 45293 | C4: 6233.42 | G4: Q1 2025 | H4: =D250 -> 5190.0984 | I4: =H4-H3 -> -53.53362
B5: 45294 | C5: 6236.07 | G5: Q2 2025 | H5: =D304 -> 4878.9333 | I5: =H5-H4 -> -311.16509
B6: 45295 | C6: 6244.17 | G6: Q3 2025 | H6: =D366 -> 5357.3376 | I6: =H6-H5 -> 478.40425
B7: 45299 | C7: 6269.51
B8: 45300 | C8: 6267.82
B9: 45301 | C9: 6285.25
B10: 45302 | C10: 6301.7
B11: 45306 | C11: 6318.08
B12: 45307 | C12: 6331.61
B13: 45308 | C13: 6346.21
B14: 45309 | C14: 6336.76
B15: 45313 | C15: 6254.31
B16: 45314 | C16: 6276.26
B17: 45315 | C17: 6226.65
B18: 45316 | C18: 6156.41
... B191: 45650 | C191: 5169.32
B192: 45652 | C192: 5184.45 | D192: Q4 2024
B193: 45656 | C193: 5216.44 | D193: =AVERAGE(C145:C193) -> 5243.632
B194: 45658 | C194: 5218.16
B195: 45659 | C195: 5199.62
B196: 45663 | C196: 5198.84
B197: 45664 | C197: 5190.78
B198: 45665 | C198: 5185
B199: 45666 | C199: 5194.43
B200: 45670 | C200: 5151.88
B201: 45671 | C201: 5150.87
B202: 45672 | C202: 5142.52
B203: 45673 | C203: 5133.92
B204: 45677 | C204: 5195.83
B205: 45678 | C205: 5202.62
... B248: 45740 | C248: 5196.89
B249: 45741 | C249: 5214.21 | D249: Q1 2025
B250: 45743 | C250: 5219.16 | D250: =AVERAGE(C194:C250) -> 5190.0984 | E250: =D250-D193 -> -53.53362
B251: 45753 | C251: 5205.19
B252: 45754 | C252: 5196.7
B253: 45755 | C253: 5185.83
B254: 45756 | C254: 5196.05
B255: 45757 | C255: 5205.23
...

Sheet Returns
B2: Stock Returns
B4: Quarter | C4: Date | D4: UCB | E4: IDLC | F4: GP | G4: BATASHOE | H4: RENATA | I4: WALTONHIL | J4: RAKC | K4: OLYMPIC | L4: No. of Trading Days
B5: 2024 Q1 | C5: 45292 | L5: 60
C6: 45293 | D6: =Data!I4 -> 0 | E6: =Data!Q4 -> 0 | F6: =Data!Y4 -> 0 | G6: =Data!AG4 -> -0.0054982243 | H6: =Data!AO4 -> 0 | I6: =Data!AW4 -> 0 | J6: =Data!BE4 -> 0 | K6: =Data!BM4 -> 0.0052770571
C7: 45294 | D7: =Data!I5 -> 0 | E7: =Data!Q5 -> 0 | F7: =Data!Y5 -> 0 | G7: =Data!AG5 -> -0.00010403121 | H7: =Data!AO5 -> 0 | I7: =Data!AW5 -> 0 | J7: =Data!BE5 -> 0 | K7: =Data!BM5 -> 0.015018239
C8: 45295 | D8: =Data!I6 -> 0 | E8: =Data!Q6 -> 0 | F8: =Data!Y6 -> 0 | G8: =Data!AG6 -> 0.0076692261 | H8: =Data!AO6 -> 0 | I8: =Data!AW6 -> 0 | J8: =Data!BE6 -> 0 | K8: =Data!BM6 -> 0.012878478
C9: 45299 | D9: =Data!I7 -> 0 | E9: =Data!Q7 -> 0 | F9: =Data!Y7 -> 0 | G9: =Data!AG7 -> 0.00082559344 | H9: =Data!AO7 -> 0 | I9: =Data!AW7 -> 0 | J9: =Data!BE7 -> 0 | K9: =Data!BM7 -> -0.0051315058
C10: 45300 | D10: =Data!I8 -> 0 | E10: =Data!Q8 -> 0 | F10: =Data!Y8 -> 0 | G10: =Data!AG8 -> -0.0066239116 | H10: =Data!AO8 -> 0 | I10: =Data!AW8 -> 0 | J10: =Data!BE8 -> 0 | K10: =Data!BM8 -> -0.0019311239
C11: 45301 | D11: =Data!I9 -> 0 | E11: =Data!Q9 -> 0 | F11: =Data!Y9 -> 0 | G11: =Data!AG9 -> 0.012384059 | H11: =Data!AO9 -> 0 | I11: =Data!AW9 -> 0 | J11: =Data!BE9 -> 0 | K11: =Data!BM9 -> 0.0012878302
C12: 45302 | D12: =Data!I10 -> 0 | E12: =Data!Q10 -> 0 | F12: =Data!Y10 -> 0 | G12: =Data!AG10 -> -0.0060696653 | H12: =Data!AO10 -> 0 | I12: =Data!AW10 -> 0 | J12: =Data!BE10 -> 0 | K12: =Data!BM10 -> -0.0038684768
C13: 45305 | D13: =Data!I11 -> 0 | E13: =Data!Q11 -> 0 | F13: =Data!Y11 -> 0 | G13: =Data!AG11 -> 0.0099595258 | H13: =Data!AO11 -> 0 | I13: =Data!AW11 -> 0 | J13: =Data!BE11 -> 0 | K13: =Data!BM11 -> 0.0025806466
C14: 45306 | D14: =Data!I12 -> 0 | E14: =Data!Q12 -> 0 | F14: =Data!Y12 -> 0 | G14: =Data!AG12 -> 0.0047903063 | H14: =Data!AO12 -> 0 | I14: =Data!AW12 -> 0 | J14: =Data!BE12 -> 0 | K14: =Data!BM12 -> 0.0102565
C15: 45307 | D15: =Data!I13 -> 0 | E15: =Data!Q13 -> 0 | F15: =Data!Y13 -> 0 | G15: =Data!AG13 -> -0.00050851768 | H15: =Data!AO13 -> 0 | I15: =Data!AW13 -> 0 | J15: =Data!BE13 -> 0 | K15: =Data!BM13 -> -0.0031938705
C16: 45308 | D16: =Data!I14 -> 0 | E16: =Data!Q14 -> 0 | F16: =Data!Y14 -> 0 | G16: =Data!AG14 -> 0.011932592 | H16: =Data!AO14 -> 0 | I16: =Data!AW14 -> 0 | J16: =Data!BE14 -> 0 | K16: =Data!BM14 -> -0.0070626297
C17: 45309 | D17: =Data!I15 -> 0 | E17: =Data!Q15 -> 0 | F17: =Data!Y15 -> 0 | G17: =Data!AG15 -> -0.0072639545 | H17: =Data!AO15 -> 0 | I17: =Data!AW15 -> 0 | J17: =Data!BE15 -> 0 | K17: =Data!BM15 -> -0.0064641466
... C64: 45382 | D64: =Data!I62 -> 0.0083682497 | E64: =Data!Q62 -> 0.016529302 | F64: =Data!Y62 -> 0.0084459962 | G64: =Data!AG62 -> 0.0080231985 | H64: =Data!AO62 -> 0.011926509 | I64: =Data!AW62 -> -0.0088835015 | J64: =Data!BE62 -> 0.024845999 | K64: =Data!BM62 -> 0.016573134
B65: 2024 Q2 | C65: 45383 | D65: =Data!I63 -> -0.025317808 | E65: =Data!Q63 -> 0.0027285147 | F65: =Data!Y63 -> -0.0037918731 | G65: =Data!AG63 -> 0.0046422528 | H65: =Data!AO63 -> -0.035814151 | I65: =Data!AW63 -> -0.00030773965 | J65: =Data!BE63 -> -0.0061538656 | K65: =Data!BM63 -> 0.0052459137 | L65: 56
C66: 45384 | D66: =Data!I64 -> -0.0085837437 | E66: =Data!Q64 -> 0 | F66: =Data!Y64 -> 0.0033712632 | G66: =Data!AG64 -> 0.0025139538 | H66: =Data!AO64 -> 0.020622013 | I66: =Data!AW64 -> 0.033742516 | J66: =Data!BE64 -> -0.0093023927 | K66: =Data!BM64 -> 0.0039164541
C67: 45385 | D67: =Data!I65 -> 0.0085837437 | E67: =Data!Q65 -> 0.016216572 | F67: =Data!Y65 -> 0.0079614919 | G67: =Data!AG65 -> 0.0060078282 | H67: =Data!AO65 -> 0.0027438444 | I67: =Data!AW65 -> 0.011832707 | J67: =Data!BE65 -> 0.015456258 | K67: =Data!BM65 -> 0.0058460706
C68: 45386 | D68: =Data!I66 -> -0.017241806 | E68: =Data!Q66 -> 0 | F68: =Data!Y66 -> 0.0025010434 | G68: =Data!AG66 -> -0.011748892 | H68: =Data!AO66 -> 0.0033867428 | I68: =Data!AW66 -> -0.0082681705 | J68: =Data!BE66 -> 0.006116227 | K68: =Data!BM66 -> -0.00064787822
C69: 45390 | D69: =Data!I67 -> 0.0086580627 | E69: =Data!Q67 -> 0.0053476063 | F69: =Data!Y67 -> 0 | G69: =Data!AG67 -> 0.0078479123 | H69: =Data!AO67 -> 0.013946507 | I69: =Data!AW67 -> 0.0079740529 | J69: =Data!BE67 -> 0.015128882 | K69: =Data!BM67 -> 0.0051713108
C70: 45391 | D70: =Data!I68 -> -0.017391743 | E70: =Data!Q68 -> 0.0082988028 | F70: =Data!Y68 -> -0.0008329863 | G70: =Data!AG68 -> -0.0030111435 | H70: =Data!AO68 -> 0.034162268 | I70: =Data!AW68 -> -0.0088639966 | J70: =Data!BE68 -> 0.014903406 | K70: =Data!BM68 -> -0.013632149
C71: 45397 | D71: =Data!I69 -> 0 | E71: =Data!Q69 -> -0.025105921 | F71: =Data!Y69 -> -0.004593869 | G71: =Data!AG69 -> -0.0056451763 | H71: =Data!AO69 -> 0.00037172418 | I71: =Data!AW69 -> -0.019025366 | J71: =Data!BE69 -> -0.039220713 | K71: =Data!BM69 -> -0.019802627
C72: 45398 | D72: =Data!I70 -> 0.00873368 | E72: =Data!Q70 -> -0.0028288562 | F72: =Data!Y70 -> -0.01178961 | G72: =Data!AG70 -> -0.0090378884 | H72: =Data!AO70 -> 0.00074303409 | I72: =Data!AW70 -> -0.0018165309 | J72: =Data!BE70 -> -0.0061728591 | K72: =Data!BM70 -> 0.011928571
C73: 45399 | D73: =Data!I71 -> 0 | E73: =Data!Q71 -> -0.0056818335 | F73: =Data!Y71 -> 0.0033826671 | G73: =Data!AG71 -> 0.0017326611 | H73: =Data!AO71 -> 0.0062935976 | I73: =Data!AW71 -> -0.012962438 | J73: =Data!BE71 -> -0.01246122 | K73: =Data!BM71 -> 0.0085274377
C74: 45400 | D74: =Data!I72 -> -0.00873368 | E74: =Data!Q72 -> -0.055651255 | F74: =Data!Y72 -> -0.0093300083 | G74: =Data!AG72 -> -0.017152374 | H74: =Data!AO72 -> -0.015496498 | I74: =Data!AW72 -> -0.0080136043 | J74: =Data!BE72 -> -0.015798117 | K74: =Data!BM72 -> -0.02983317
C75: 45403 | D75: =Data!I73 -> -0.035718083 | E75: =Data!Q73 -> -0.024391453 | F75: =Data!Y73 -> -0.0021326517 | G75: =Data!AG73 -> 0.0048571376 | H75: =Data!AO73 -> -0.022745484 | I75: =Data!AW73 -> -0.022532638 | J75: =Data!BE73 -> -0.0031897954 | K75: =Data!BM73 -> 0.0013449901
C76: 45404 | D76: =Data!I74 -> 0.0090498355 | E76: =Data!Q74 -> 0.015314235 | F76: =Data!Y74 -> -0.0047079051 | G76: =Data!AG74 -> 0 | H76: =Data!AO74 -> 0.00089428304 | I76: =Data!AW74 -> 0.021448963 | J76: =Data!BE74 -> 0 | K76: =Data!BM74 -> -0.0053908486
C77: 45405 | D77: =Data!I75 -> -0.027398974 | E77: =Data!Q75 -> -0.0091603694 | F77: =Data!Y75 -> -0.002147306 | G77: =Data!AG75 -> -0.015061308 | H77: =Data!AO75 -> 0.0048407738 | I77: =Data!AW75 -> 0.0083295253 | J77: =Data!BE75 -> -0.039092926 | K77: =Data!BM75 -> -0.003384098
... C120: 45473 | D120: =Data!I118 -> -0.023810649 | E120: =Data!Q118 -> -0.020134908 | F120: =Data!Y118 -> 0.025763028 | G120: =Data!AG118 -> 0.019321777 | H120: =Data!AO118 -> 0.0054687636 | I120: =Data!AW118 -> -0.0047622795 | J120: =Data!BE118 -> -0.015151805 | K120: =Data!BM118 -> -0.0060241146
B121: 2024 Q3 | C121: 45475 | D121: =Data!I119 -> 0 | E121: =Data!Q119 -> -0.003395589 | F121: =Data!Y119 -> -0.015050111 | G121: =Data!AG119 -> -0.022770597 | H121: =Data!AO119 -> -0.017685664 | I121: =Data!AW119 -> -0.0015410698 | J121: =Data!BE119 -> -0.011516442 | K121: =Data!BM119 -> -0.019832839 | L121: 58
C122: 45476 | D122: =Data!I120 -> 0.023810649 | E122: =Data!Q120 -> 0.033447934 | F122: =Data!Y120 -> -0.015696316 | G122: =Data!AG120 -> 0.00041867281 | H122: =Data!AO120 -> -0.017465946 | I122: =Data!AW120 -> 0.010890513 | J122: =Data!BE120 -> 0.022901764 | K122: =Data!BM120 -> -0.0054075064
C123: 45477 | D123: =Data!I121 -> 0.034685558 | E123: =Data!Q121 -> 0.066797481 | F123: =Data!Y121 -> 0.022232287 | G123: =Data!AG121 -> 0.016295965 | H123: =Data!AO121 -> 0.021423213 | I123: =Data!AW121 -> 0.0039585923 | J123: =Data!BE121 -> 0.037041272 | K123: =Data!BM121 -> 0.029009668
C124: 45480 | D124: =Data!I122 -> 0.044451763 | E124: =Data!Q122 -> 0.039220713 | F124: =Data!Y122 -> 0.022545238 | G124: =Data!AG122 -> 0.0065674941 | H124: =Data!AO122 -> -0.0070018121 | I124: =Data!AW122 -> -0.03023522 | J124: =Data!BE122 -> 0.021583572 | K124: =Data!BM122 -> 0.0089888246
C125: 45481 | D125: =Data!I123 -> 0 | E125: =Data!Q123 -> -0.017910927 | F125: =Data!Y123 -> -0.0096000737 | G125: =Data!AG123 -> -0.018165429 | H125: =Data!AO123 -> -0.0034528587 | I125: =Data!AW123 -> -0.026824876 | J125: =Data!BE123 -> -0.014337163 | K125: =Data!BM123 -> -0.0029873062
C126: 45482 | D126: =Data!I124 -> -0.010929071 | E126: =Data!Q124 -> -0.024391453 | F126: =Data!Y124 -> -0.01498307 | G126: =Data!AG124 -> -0.013316055 | H126: =Data!AO124 -> -0.0026641817 | I126: =Data!AW124 -> -0.0020935671 | J126: =Data!BE124 -> 0.031974305 | K126: =Data!BM124 -> -0.0029962569
C127: 45483 | D127: =Data!I125 -> 0.021739987 | E127: =Data!Q125 -> 0.024391453 | F127: =Data!Y125 -> -0.0016333201 | G127: =Data!AG125 -> 0.0051587207 | H127: =Data!AO125 -> -0.009246297 | I127: =Data!AW125 -> -0.014615395 | J127: =Data!BE125 -> -0.0035026306 | K127: =Data!BM125 -> 0.022989518
C128: 45484 | D128: =Data!I126 -> -0.021739987 | E128: =Data!Q126 -> -0.021309787 | F128: =Data!Y126 -> -0.0049160279 | G128: =Data!AG126 -> -0.0099198787 | H128: =Data!AO126 -> -0.0062120389 | I128: =Data!AW126 -> -0.023000931 | J128: =Data!BE126 -> -0.028471674 | K128: =Data!BM126 -> -0.028254668
C129: 45487 | D129: =Data!I127 -> -0.011049836 | E129: =Data!Q127 -> -0.0092736368 | F129: =Data!Y127 -> 0.0040983664 | G129: =Data!AG127 -> 0.018597857 | H129: =Data!AO127 -> -0.005024795 | I129: =Data!AW127 -> -0.012803409 | J129: =Data!BE127 -> -0.021898685 | K129: =Data!BM127 -> -0.018265348
C130: 45488 | D130: =Data!I128 -> 0 | E130: =Data!Q128 -> 0.0031007777 | F130: =Data!Y128 -> 0.00040891434 | G130: =Data!AG128 -> -0.016161544 | H130: =Data!AO128 -> 0.0017683471 | I130: =Data!AW128 -> 0.072265458 | J130: =Data!BE128 -> -0.0074074413 | K130: =Data!BM128 -> -0.0046189459
...

Sheet Forcast 2025Q1
B2: Forecast Q1 2025
C4: UCB | D4: IDLC | E4: GP | F4: BATASHOE | G4: RENATA | H4: WALTONHIL | I4: RAKC | J4: OLYMPIC | K4: Weights
B5: Weights | C5: 0.125 | D5: 0.125 | E5: 0.125 | F5: 0.125 | G5: 0.125 | H5: 0.125 | I5: 0.125 | J5: 0.125 | M5: Q1 2025
B6: ='Stock Selection'!C5 -> UCB | C6: =VARP(Returns!$D$6:$D$239) -> 0.00064885675 | D6: 0.00022769737 | E6: 0.00019397746 | F6: 5.7159373e-05 | G6: 0.0001103972 | H6: 9.938745e-05 | I6: 0.0002247945 | J6: 0.00014347402 | K6: 0.125 | M6: Portfolio Variance | P6: =MMULT(MMULT(C5:J5,C6:J13),K6:K13) -> 0.00020994703
B7: ='Stock Selection'!C6 -> IDLC | C7: 0.00022769737 | D7: =VARP(Returns!$E$6:$E$239) -> 0.00061207392 | E7: 0.00024598434 | F7: 0.00010330646 | G7: 0.00017700343 | H7: 0.00027099648 | I7: 0.00033436751 | J7: 0.00028662625 | K7: 0.125 | M7: Portfolio Standard Deviation | P7: =SQRT(P6) -> 0.014489549
B8: ='Stock Selection'!C7 -> GP | C8: 0.00019397746 | D8: 0.00024598434 | E8: =VARP(Returns!$F$6:$F$239) -> 0.00032926845 | F8: 6.3159963e-05 | G8: 0.0001811601 | H8: 0.000147565 | I8: 0.00015861336 | J8: 0.0001917167 | K8: 0.125 | M8: Quarterly Portfolio SD | P8: =P7*P9^0.5 -> 0.113167
B9: ='Stock Selection'!C8 -> BATASHOE | C9: 5.7159373e-05 | D9: 0.00010330646 | E9: 6.3159963e-05 | F9: =VARP(Returns!$G$6:$G$239) -> 0.00014397657 | G9: 6.9401378e-05 | H9: 8.3384363e-05 | I9: 0.00010129654 | J9: 7.9539258e-05 | K9: 0.125 | M9: Trading Days | P9: =Returns!L240 -> 61
B10: ='Stock Selection'!C9 -> RENATA | C10: 0.0001103972 | D10: 0.00017700343 | E10: 0.0001811601 | F10: 6.9401378e-05 | G10: =VARP(Returns!$H$6:$H$239) -> 0.00042423911 | H10: 0.00019402032 | I10: 0.00016509768 | J10: 0.00012489838 | K10: 0.125
B11: ='Stock Selection'!C10 -> WALTONHIL | C11: 9.938745e-05 | D11: 0.00027099648 | E11: 0.000147565 | F11: 8.3384363e-05 | G11: 0.00019402032 | H11: =VARP(Returns!$I$6:$I$239) -> 0.00065914533 | I11: 0.00027741736 | J11: 0.00015477947 | K11: 0.125
B12: ='Stock Selection'!C11 -> RAKC | C12: 0.0002247945 | D12: 0.00033436751 | E12: 0.00015861336 | F12: 0.00010129654 | G12: 0.00016509768 | H12: 0.00027741736 | I12: =VARP(Returns!$J$6:$J$239) -> 0.00065062327 | J12: 0.00021941036 | K12: 0.125
B13: ='Stock Selection'!C12 -> OLYMPIC | C13: 0.00014347402 | D13: 0.00028662625 | E13: 0.0001917167 | F13: 7.9539258e-05 | G13: 0.00012489838 | H13: 0.00015477947 | I13: 0.00021941036 | J13: =VARP(Returns!$K$6:$K$239) -> 0.0005951623 | K13: 0.125

Sheet Forcast 2025Q2
B2: Forecast Q2 2025
C4: UCB | D4: IDLC | E4: GP | F4: BATASHOE | G4: RENATA | H4: WALTONHIL | I4: RAKC | J4: OLYMPIC | K4: Weights
B5: Weights | C5: 0.125 | D5: 0.125 | E5: 0.125 | F5: 0.125 | G5: 0.125 | H5: 0.125 | I5: 0.125 | J5: 0.125 | M5: Q2 2025
B6: ='Stock Selection'!C5 -> UCB | C6: =VARP(Returns!$D$65:$D$300) -> 0.00068289667 | D6: 0.00022148298 | E6: 0.00018780466 | F6: 4.6455851e-05 | G6: 0.00013057235 | H6: 0.00010509688 | I6: 0.00018703653 | J6: 0.00014082131 | K6: 0.125 | M6: Portfolio Variance | P6: =MMULT(MMULT(C5:J5,C6:J13),K6:K13) -> 0.00019557536
B7: ='Stock Selection'!C6 -> IDLC | C7: 0.00022148298 | D7: =VARP(Returns!$E$65:$E$300) -> 0.00051645367 | E7: 0.00023610813 | F7: 0.0001109935 | G7: 0.00017618451 | H7: 0.00020112237 | I7: 0.00027977845 | J7: 0.00027495276 | K7: 0.125 | M7: Portfolio Standard Deviation | P7: =SQRT(P6) -> 0.013984826
B8: ='Stock Selection'!C7 -> GP | C8: 0.00018780466 | D8: 0.00023610813 | E8: =VARP(Returns!$F$65:$F$300) -> 0.00031619601 | F8: 6.5073022e-05 | G8: 0.00017370801 | H8: 0.0001432714 | I8: 0.00015318299 | J8: 0.00018890659 | K8: 0.125 | M8: Quarterly Portfolio SD | P8: =P7*P9^0.5 -> 0.10371425
B9: ='Stock Selection'!C8 -> BATASHOE | C9: 4.6455851e-05 | D9: 0.0001109935 | E9: 6.5073022e-05 | F9: =VARP(Returns!$G$65:$G$300) -> 0.00017802672 | G9: 7.4627615e-05 | H9: 9.4693178e-05 | I9: 8.4122357e-05 | J9: 8.1908455e-05 | K9: 0.125 | M9: Trading Days | P9: =Returns!L301 -> 55
B10: ='Stock Selection'!C9 -> RENATA | C10: 0.00013057235 | D10: 0.00017618451 | E10: 0.00017370801 | F10: 7.4627615e-05 | G10: =VARP(Returns!$H$65:$H$300) -> 0.00038278308 | H10: 0.0001771044 | I10: 0.00017260885 | J10: 0.00011894446 | K10: 0.125
B11: ='Stock Selection'!C10 -> WALTONHIL | C11: 0.00010509688 | D11: 0.00020112237 | E11: 0.0001432714 | F11: 9.4693178e-05 | G11: 0.0001771044 | H11: =VARP(Returns!$I$65:$I$300) -> 0.00049172163 | I11: 0.00019035703 | J11: 0.00016974052 | K11: 0.125
B12: ='Stock Selection'!C11 -> RAKC | C12: 0.00018703653 | D12: 0.00027977845 | E12: 0.00015318299 | F12: 8.4122357e-05 | G12: 0.00017260885 | H12: 0.00019035703 | I12: =VARP(Returns!$J$65:$J$300) -> 0.00055020141 | J12: 0.00022080993 | K12: 0.125
B13: ='Stock Selection'!C12 -> OLYMPIC | C13: 0.00014082131 | D13: 0.00027495276 | E13: 0.00018890659 | F13: 8.1908455e-05 | G13: 0.00011894446 | H13: 0.00016974052 | I13: 0.00022080993 | J13: =VARP(Returns!$K$65:$K$300) -> 0.00058360583 | K13: 0.125

Sheet Forcast 2025Q3
B2: Forecast Q3 2025
C4: UCB | D4: IDLC | E4: GP | F4: BATASHOE | G4: RENATA | H4: WALTONHIL | I4: RAKC | J4: OLYMPIC | K4: Weights
B5: Weights | C5: 0.125 | D5: 0.125 | E5: 0.125 | F5: 0.125 | G5: 0.125 | H5: 0.125 | I5: 0.125 | J5: 0.125 | M5: Q3 2025
B6: ='Stock Selection'!C5 -> UCB | C6: =VARP(Returns!$D$121:$D$355) -> 0.00078245028 | D6: 0.00026981402 | E6: 0.00019322445 | F6: 5.560698e-05 | G6: 0.00016310997 | H6: 0.00011227986 | I6: 0.00024002794 | J6: 0.00013437567 | K6: 0.125 | M6: Portfolio Variance | P6: =MMULT(MMULT(C5:J5,C6:J13),K6:K13) -> 0.00018452565
B7: ='Stock Selection'!C6 -> IDLC | C7: 0.00026981402 | D7: =VARP(Returns!$E$121:$E$355) -> 0.00049585688 | E7: 0.00023611878 | F7: 9.3939882e-05 | G7: 0.0001448042 | H7: 0.00016541448 | I7: 0.00025530735 | J7: 0.00025180181 | K7: 0.125 | M7: Portfolio Standard Deviation | P7: =SQRT(P6) -> 0.013584022
B8: ='Stock Selection'!C7 -> GP | C8: 0.00019322445 | D8: 0.00023611878 | E8: =VARP(Returns!$F$121:$F$355) -> 0.00032459544 | F8: 5.0807783e-05 | G8: 0.00016042601 | H8: 0.00013134271 | I8: 0.00014113956 | J8: 0.00018895355 | K8: 0.125 | M8: Quarterly Portfolio SD | P8: =P7*P9^0.5 -> 0.10781983
B9: ='Stock Selection'!C8 -> BATASHOE | C9: 5.560698e-05 | D9: 9.3939882e-05 | E9: 5.0807783e-05 | F9: =VARP(Returns!$G$121:$G$355) -> 0.00022543235 | G9: 4.3312823e-05 | H9: 7.4597745e-05 | I9: 7.7085519e-05 | J9: 7.324857e-05 | K9: 0.125 | M9: Trading Days | P9: =Returns!L356 -> 63
B10: ='Stock Selection'!C9 -> RENATA | C10: 0.00016310997 | D10: 0.0001448042 | E10: 0.00016042601 | F10: 4.3312823e-05 | G10: =VARP(Returns!$H$121:$H$355) -> 0.00029151489 | H10: 9.6365628e-05 | I10: 0.00013500997 | J10: 9.3941835e-05 | K10: 0.125
B11: ='Stock Selection'!C10 -> WALTONHIL | C11: 0.00011227986 | D11: 0.00016541448 | E11: 0.00013134271 | F11: 7.4597745e-05 | G11: 9.6365628e-05 | H11: =VARP(Returns!$I$121:$I$355) -> 0.00034839047 | I11: 0.00015826149 | J11: 0.000145558 | K11: 0.125
B12: ='Stock Selection'!C11 -> RAKC | C12: 0.00024002794 | D12: 0.00025530735 | E12: 0.00014113956 | F12: 7.7085519e-05 | G12: 0.00013500997 | H12: 0.00015826149 | I12: =VARP(Returns!$J$121:$J$355) -> 0.00055161501 | J12: 0.00021673748 | K12: 0.125
B13: ='Stock Selection'!C12 -> OLYMPIC | C13: 0.00013437567 | D13: 0.00025180181 | E13: 0.00018895355 | F13: 7.324857e-05 | G13: 9.3941835e-05 | H13: 0.000145558 | I13: 0.00021673748 | J13: =VARP(Returns!$K$121:$K$355) -> 0.00058455807 | K13: 0.125

Sheet 91Day T-Bill
C2: 91 Day Treasury Bill Rate
C4: Quarter 4 2024 | E4: Quarter 1 2025 | G4: Quarter 2 2025
C5: Issue Date | D5: Annual Rate | E5: Issue Date | F5: Annual Rate | G5: Issue Date | H5: Annual Rate
C6: 45572 | D6: 0.114499 | E6: 45663 | F6: 0.114299 | G6: 45754 | H6: 0.112391
C7: 45579 | D7: 0.114499 | E7: 45670 | F7: 0.113387 | G7: 45762 | H7: 0.114495
C8: 45587 | D8: 0.117501 | E8: 45677 | F8: 0.1129 | G8: 45768 | H8: 0.115895
C9: 45593 | D9: 0.117501 | E9: 45684 | F9: 0.111302 | G9: 45775 | H9: 0.116401
C10: 45600 | D10: 0.117501 | E10: 45691 | F10: 0.108499 | G10: 45782 | H10: 0.116099
C11: 45607 | D11: 0.117501 | E11: 45698 | F11: 0.105392 | G11: 45789 | H11: 0.115394
C12: 45614 | D12: 0.117501 | E12: 45705 | F12: 0.1035 | G12: 45796 | H12: 0.116498
C13: 45621 | D13: 0.117501 | E13: 45712 | F13: 0.1035 | G13: 45803 | H13: 0.116881
C14: 45628 | D14: 0.117097 | E14: 45719 | F14: 0.103399 | G14: 45810 | H14: 0.120197
C15: 45635 | D15: 0.116507 | E15: 45726 | F15: 0.1035 | G15: 45824 | H15: 0.121001
C16: 45643 | D16: 0.115691 | E16: 45733 | F16: 0.107497 | G16: 45831 | H16: 0.120891
C17: 45649 | D17: 0.114991 | E17: 45740 | F17: 0.108998 | G17: 45838 | H17: 0.120899
C18: 45656 | D18: 0.115
C20: Particulars | F20: 2025 Q1 | G20: 2025 Q2 | H20: 2025 Q3
C21: Average Annual Risk-Free Rate | F21: =AVERAGE(D6:D18) -> 0.11640692 | G21: =AVERAGE(F6:F18) -> 0.10801442 | H21: =AVERAGE(H6:H18) -> 0.1172535
C22: Continuously Compounding Annual Risk-Free Rate | F22: =4*LN(1+(F21/4)) -> 0.11474526 | G22: =4*LN(1+(G21/4)) -> 0.10658176 | H22: =4*LN(1+(H21/4)) -> 0.11556781
C23: Continuously Compounding Daily Risk-Free Rate | F23: =F22/364 -> 0.00031523424 | G23: =G22/364 -> 0.00029280704 | H23: =H22/364 -> 0.000317494
